[2022-09-14 04:56:10,170] {taskinstance.py:1159} INFO - Dependencies all met for <TaskInstance: user_processing.process_user manual__2022-09-14T04:56:07.957120+00:00 [queued]>
[2022-09-14 04:56:10,186] {taskinstance.py:1159} INFO - Dependencies all met for <TaskInstance: user_processing.process_user manual__2022-09-14T04:56:07.957120+00:00 [queued]>
[2022-09-14 04:56:10,187] {taskinstance.py:1356} INFO - 
--------------------------------------------------------------------------------
[2022-09-14 04:56:10,188] {taskinstance.py:1357} INFO - Starting attempt 1 of 1
[2022-09-14 04:56:10,189] {taskinstance.py:1358} INFO - 
--------------------------------------------------------------------------------
[2022-09-14 04:56:10,203] {taskinstance.py:1377} INFO - Executing <Task(PythonOperator): process_user> on 2022-09-14 04:56:07.957120+00:00
[2022-09-14 04:56:10,213] {standard_task_runner.py:52} INFO - Started process 13345 to run task
[2022-09-14 04:56:10,220] {standard_task_runner.py:79} INFO - Running: ['***', 'tasks', 'run', 'user_processing', 'process_user', 'manual__2022-09-14T04:56:07.957120+00:00', '--job-id', '26', '--raw', '--subdir', 'DAGS_FOLDER/user_processing.py', '--cfg-path', '/tmp/tmpllp0l536', '--error-file', '/tmp/tmphm918x75']
[2022-09-14 04:56:10,221] {standard_task_runner.py:80} INFO - Job 26: Subtask process_user
[2022-09-14 04:56:10,299] {task_command.py:369} INFO - Running <TaskInstance: user_processing.process_user manual__2022-09-14T04:56:07.957120+00:00 [running]> on host 5282528dd996
[2022-09-14 04:56:10,376] {taskinstance.py:1571} INFO - Exporting the following env vars:
AIRFLOW_CTX_DAG_OWNER=***
AIRFLOW_CTX_DAG_ID=user_processing
AIRFLOW_CTX_TASK_ID=process_user
AIRFLOW_CTX_EXECUTION_DATE=2022-09-14T04:56:07.957120+00:00
AIRFLOW_CTX_TRY_NUMBER=1
AIRFLOW_CTX_DAG_RUN_ID=manual__2022-09-14T04:56:07.957120+00:00
[2022-09-14 04:56:10,456] {taskinstance.py:1889} ERROR - Task failed with exception
Traceback (most recent call last):
  File "/home/airflow/.local/lib/python3.7/site-packages/airflow/operators/python.py", line 171, in execute
    return_value = self.execute_callable()
  File "/home/airflow/.local/lib/python3.7/site-packages/airflow/operators/python.py", line 189, in execute_callable
    return self.python_callable(*self.op_args, **self.op_kwargs)
  File "/opt/airflow/dags/user_processing.py", line 14, in _process_user
    user= user['results'][0]
TypeError: 'NoneType' object is not subscriptable
[2022-09-14 04:56:10,514] {taskinstance.py:1400} INFO - Marking task as FAILED. dag_id=user_processing, task_id=process_user, execution_date=20220914T045607, start_date=20220914T045610, end_date=20220914T045610
[2022-09-14 04:56:10,552] {standard_task_runner.py:97} ERROR - Failed to execute job 26 for task process_user ('NoneType' object is not subscriptable; 13345)
[2022-09-14 04:56:10,600] {local_task_job.py:156} INFO - Task exited with return code 1
[2022-09-14 04:56:10,771] {local_task_job.py:273} INFO - 0 downstream tasks scheduled from follow-on schedule check
