[2022-09-14 05:05:22,796] {taskinstance.py:1159} INFO - Dependencies all met for <TaskInstance: user_processing.is_api_available __airflow_temporary_run_2022-09-14T05:05:21.410315+00:00__ [queued]>
[2022-09-14 05:05:22,805] {taskinstance.py:1159} INFO - Dependencies all met for <TaskInstance: user_processing.is_api_available __airflow_temporary_run_2022-09-14T05:05:21.410315+00:00__ [queued]>
[2022-09-14 05:05:22,806] {taskinstance.py:1356} INFO - 
--------------------------------------------------------------------------------
[2022-09-14 05:05:22,807] {taskinstance.py:1357} INFO - Starting attempt 1 of 1
[2022-09-14 05:05:22,807] {taskinstance.py:1358} INFO - 
--------------------------------------------------------------------------------
[2022-09-14 05:05:22,820] {taskinstance.py:1377} INFO - Executing <Task(HttpSensor): is_api_available> on 2022-09-14 00:00:00+00:00
[2022-09-14 05:05:22,829] {standard_task_runner.py:52} INFO - Started process 13828 to run task
[2022-09-14 05:05:22,834] {standard_task_runner.py:79} INFO - Running: ['***', 'tasks', 'run', 'user_processing', 'is_api_available', '__***_temporary_run_2022-09-14T05:05:21.410315+00:00__', '--job-id', '35', '--raw', '--subdir', 'DAGS_FOLDER/user_processing.py', '--cfg-path', '/tmp/tmp307ewvdi', '--error-file', '/tmp/tmpkiw6ffyo']
[2022-09-14 05:05:22,836] {standard_task_runner.py:80} INFO - Job 35: Subtask is_api_available
[2022-09-14 05:05:22,957] {task_command.py:369} INFO - Running <TaskInstance: user_processing.is_api_available __airflow_temporary_run_2022-09-14T05:05:21.410315+00:00__ [running]> on host 5282528dd996
[2022-09-14 05:05:23,205] {taskinstance.py:1571} INFO - Exporting the following env vars:
AIRFLOW_CTX_DAG_OWNER=***
AIRFLOW_CTX_DAG_ID=user_processing
AIRFLOW_CTX_TASK_ID=is_api_available
AIRFLOW_CTX_EXECUTION_DATE=2022-09-14T00:00:00+00:00
AIRFLOW_CTX_TRY_NUMBER=1
AIRFLOW_CTX_DAG_RUN_ID=__***_temporary_run_2022-09-14T05:05:21.410315+00:00__
[2022-09-14 05:05:23,213] {http.py:97} INFO - Poking: api/
[2022-09-14 05:05:23,292] {base.py:68} INFO - Using connection ID 'user_api' for task execution.
[2022-09-14 05:05:23,316] {http.py:129} INFO - Sending 'GET' to url: https://randomuser.me/api/
[2022-09-14 05:05:27,971] {local_task_job.py:221} WARNING - State of this instance has been externally set to None. Terminating instance.
[2022-09-14 05:05:27,981] {process_utils.py:129} INFO - Sending Signals.SIGTERM to group 13828. PIDs of all processes in the group: [13828]
[2022-09-14 05:05:27,982] {process_utils.py:80} INFO - Sending the signal Signals.SIGTERM to group 13828
[2022-09-14 05:05:27,990] {taskinstance.py:1541} ERROR - Received SIGTERM. Terminating subprocesses.
[2022-09-14 05:05:28,019] {taskinstance.py:1889} ERROR - Task failed with exception
Traceback (most recent call last):
  File "/home/airflow/.local/lib/python3.7/site-packages/airflow/sensors/base.py", line 277, in execute
    poke_return = self.poke(context)
  File "/home/airflow/.local/lib/python3.7/site-packages/airflow/providers/http/sensors/http.py", line 112, in poke
    raise exc
  File "/home/airflow/.local/lib/python3.7/site-packages/airflow/providers/http/sensors/http.py", line 103, in poke
    extra_options=self.extra_options,
  File "/home/airflow/.local/lib/python3.7/site-packages/airflow/providers/http/hooks/http.py", line 130, in run
    return self.run_and_check(session, prepped_request, extra_options)
  File "/home/airflow/.local/lib/python3.7/site-packages/airflow/providers/http/hooks/http.py", line 180, in run_and_check
    response = session.send(prepped_request, **send_kwargs)
  File "/home/airflow/.local/lib/python3.7/site-packages/requests/sessions.py", line 645, in send
    r = adapter.send(request, **kwargs)
  File "/home/airflow/.local/lib/python3.7/site-packages/requests/adapters.py", line 450, in send
    timeout=timeout
  File "/home/airflow/.local/lib/python3.7/site-packages/urllib3/connectionpool.py", line 710, in urlopen
    chunked=chunked,
  File "/home/airflow/.local/lib/python3.7/site-packages/urllib3/connectionpool.py", line 449, in _make_request
    six.raise_from(e, None)
  File "<string>", line 3, in raise_from
  File "/home/airflow/.local/lib/python3.7/site-packages/urllib3/connectionpool.py", line 444, in _make_request
    httplib_response = conn.getresponse()
  File "/usr/local/lib/python3.7/http/client.py", line 1373, in getresponse
    response.begin()
  File "/usr/local/lib/python3.7/http/client.py", line 319, in begin
    version, status, reason = self._read_status()
  File "/usr/local/lib/python3.7/http/client.py", line 280, in _read_status
    line = str(self.fp.readline(_MAXLINE + 1), "iso-8859-1")
  File "/usr/local/lib/python3.7/socket.py", line 589, in readinto
    return self._sock.recv_into(b)
  File "/usr/local/lib/python3.7/ssl.py", line 1071, in recv_into
    return self.read(nbytes, buffer)
  File "/usr/local/lib/python3.7/ssl.py", line 929, in read
    return self._sslobj.read(len, buffer)
  File "/home/airflow/.local/lib/python3.7/site-packages/airflow/models/taskinstance.py", line 1543, in signal_handler
    raise AirflowException("Task received SIGTERM signal")
airflow.exceptions.AirflowException: Task received SIGTERM signal
[2022-09-14 05:05:28,030] {taskinstance.py:1400} INFO - Marking task as FAILED. dag_id=user_processing, task_id=is_api_available, execution_date=20220914T000000, start_date=20220914T050522, end_date=20220914T050528
[2022-09-14 05:05:28,053] {standard_task_runner.py:97} ERROR - Failed to execute job 35 for task is_api_available ((psycopg2.errors.ForeignKeyViolation) insert or update on table "task_fail" violates foreign key constraint "task_fail_ti_fkey"
DETAIL:  Key (dag_id, task_id, run_id, map_index)=(user_processing, is_api_available, __airflow_temporary_run_2022-09-14T05:05:21.410315+00:00__, -1) is not present in table "task_instance".

[SQL: INSERT INTO task_fail (task_id, dag_id, run_id, map_index, start_date, end_date, duration) VALUES (%(task_id)s, %(dag_id)s, %(run_id)s, %(map_index)s, %(start_date)s, %(end_date)s, %(duration)s) RETURNING task_fail.id]
[parameters: {'task_id': 'is_api_available', 'dag_id': 'user_processing', 'run_id': '__airflow_temporary_run_2022-09-14T05:05:21.410315+00:00__', 'map_index': -1, 'start_date': datetime.datetime(2022, 9, 14, 5, 5, 22, 798516, tzinfo=Timezone('UTC')), 'end_date': datetime.datetime(2022, 9, 14, 5, 5, 28, 29218, tzinfo=Timezone('UTC')), 'duration': 5}]
(Background on this error at: http://sqlalche.me/e/14/gkpj); 13828)
[2022-09-14 05:05:28,121] {process_utils.py:75} INFO - Process psutil.Process(pid=13828, status='terminated', exitcode=1, started='05:05:22') (13828) terminated with exit code 1
