[2022-09-14 05:16:54,861] {taskinstance.py:1159} INFO - Dependencies all met for <TaskInstance: user_processing.extract_user manual__2022-09-14T05:16:52.821214+00:00 [queued]>
[2022-09-14 05:16:54,884] {taskinstance.py:1159} INFO - Dependencies all met for <TaskInstance: user_processing.extract_user manual__2022-09-14T05:16:52.821214+00:00 [queued]>
[2022-09-14 05:16:54,887] {taskinstance.py:1356} INFO - 
--------------------------------------------------------------------------------
[2022-09-14 05:16:54,888] {taskinstance.py:1357} INFO - Starting attempt 1 of 1
[2022-09-14 05:16:54,890] {taskinstance.py:1358} INFO - 
--------------------------------------------------------------------------------
[2022-09-14 05:16:54,913] {taskinstance.py:1377} INFO - Executing <Task(SimpleHttpOperator): extract_user> on 2022-09-14 05:16:52.821214+00:00
[2022-09-14 05:16:54,929] {standard_task_runner.py:52} INFO - Started process 14443 to run task
[2022-09-14 05:16:54,943] {standard_task_runner.py:79} INFO - Running: ['***', 'tasks', 'run', 'user_processing', 'extract_user', 'manual__2022-09-14T05:16:52.821214+00:00', '--job-id', '50', '--raw', '--subdir', 'DAGS_FOLDER/user_processing.py', '--cfg-path', '/tmp/tmpwqom9ls6', '--error-file', '/tmp/tmp835y495x']
[2022-09-14 05:16:54,949] {standard_task_runner.py:80} INFO - Job 50: Subtask extract_user
[2022-09-14 05:16:55,052] {task_command.py:369} INFO - Running <TaskInstance: user_processing.extract_user manual__2022-09-14T05:16:52.821214+00:00 [running]> on host 5282528dd996
[2022-09-14 05:16:55,268] {taskinstance.py:1571} INFO - Exporting the following env vars:
AIRFLOW_CTX_DAG_OWNER=***
AIRFLOW_CTX_DAG_ID=user_processing
AIRFLOW_CTX_TASK_ID=extract_user
AIRFLOW_CTX_EXECUTION_DATE=2022-09-14T05:16:52.821214+00:00
AIRFLOW_CTX_TRY_NUMBER=1
AIRFLOW_CTX_DAG_RUN_ID=manual__2022-09-14T05:16:52.821214+00:00
[2022-09-14 05:16:55,277] {http.py:102} INFO - Calling HTTP method
[2022-09-14 05:16:55,299] {base.py:68} INFO - Using connection ID 'user_api' for task execution.
[2022-09-14 05:16:55,317] {http.py:129} INFO - Sending 'GET' to url: https://randomuser.me/api/
[2022-09-14 05:16:55,523] {http.py:142} ERROR - HTTP error: Internal Server Error
[2022-09-14 05:16:55,531] {http.py:143} ERROR - <html>
<head>
<title>Uh oh, something bad happened</title>
</head>
<body align='center'>
<h1 align='center'>Uh oh, something bad happened</h1>
<a class="twitter-timeline" data-width="450" data-height="700" data-theme="light" href="https://twitter.com/randomapi">Tweets by randomapi</a> <script async src="//platform.twitter.com/widgets.js" charset="utf-8"></script>
</body>
</html>

[2022-09-14 05:16:55,601] {taskinstance.py:1889} ERROR - Task failed with exception
Traceback (most recent call last):
  File "/home/airflow/.local/lib/python3.7/site-packages/airflow/providers/http/hooks/http.py", line 140, in check_response
    response.raise_for_status()
  File "/home/airflow/.local/lib/python3.7/site-packages/requests/models.py", line 960, in raise_for_status
    raise HTTPError(http_error_msg, response=self)
requests.exceptions.HTTPError: 500 Server Error: Internal Server Error for url: https://randomuser.me/api/

During handling of the above exception, another exception occurred:

Traceback (most recent call last):
  File "/home/airflow/.local/lib/python3.7/site-packages/airflow/providers/http/operators/http.py", line 104, in execute
    response = http.run(self.endpoint, self.data, self.headers, self.extra_options)
  File "/home/airflow/.local/lib/python3.7/site-packages/airflow/providers/http/hooks/http.py", line 130, in run
    return self.run_and_check(session, prepped_request, extra_options)
  File "/home/airflow/.local/lib/python3.7/site-packages/airflow/providers/http/hooks/http.py", line 183, in run_and_check
    self.check_response(response)
  File "/home/airflow/.local/lib/python3.7/site-packages/airflow/providers/http/hooks/http.py", line 144, in check_response
    raise AirflowException(str(response.status_code) + ":" + response.reason)
airflow.exceptions.AirflowException: 500:Internal Server Error
[2022-09-14 05:16:55,614] {taskinstance.py:1400} INFO - Marking task as FAILED. dag_id=user_processing, task_id=extract_user, execution_date=20220914T051652, start_date=20220914T051654, end_date=20220914T051655
[2022-09-14 05:16:55,790] {standard_task_runner.py:97} ERROR - Failed to execute job 50 for task extract_user (500:Internal Server Error; 14443)
[2022-09-14 05:16:55,900] {local_task_job.py:156} INFO - Task exited with return code 1
[2022-09-14 05:16:56,229] {local_task_job.py:273} INFO - 0 downstream tasks scheduled from follow-on schedule check
