[2022-09-14 05:03:09,174] {taskinstance.py:1159} INFO - Dependencies all met for <TaskInstance: user_processing.extract_user __airflow_temporary_run_2022-09-14T05:03:07.882955+00:00__ [queued]>
[2022-09-14 05:03:09,179] {taskinstance.py:1159} INFO - Dependencies all met for <TaskInstance: user_processing.extract_user __airflow_temporary_run_2022-09-14T05:03:07.882955+00:00__ [queued]>
[2022-09-14 05:03:09,180] {taskinstance.py:1356} INFO - 
--------------------------------------------------------------------------------
[2022-09-14 05:03:09,180] {taskinstance.py:1357} INFO - Starting attempt 1 of 1
[2022-09-14 05:03:09,181] {taskinstance.py:1358} INFO - 
--------------------------------------------------------------------------------
[2022-09-14 05:03:09,188] {taskinstance.py:1377} INFO - Executing <Task(SimpleHttpOperator): extract_user> on 2022-01-01 00:00:00+00:00
[2022-09-14 05:03:09,194] {standard_task_runner.py:52} INFO - Started process 13709 to run task
[2022-09-14 05:03:09,198] {standard_task_runner.py:79} INFO - Running: ['***', 'tasks', 'run', 'user_processing', 'extract_user', '__***_temporary_run_2022-09-14T05:03:07.882955+00:00__', '--job-id', '33', '--raw', '--subdir', 'DAGS_FOLDER/user_processing.py', '--cfg-path', '/tmp/tmpxmide7cj', '--error-file', '/tmp/tmpjpjt_h99']
[2022-09-14 05:03:09,200] {standard_task_runner.py:80} INFO - Job 33: Subtask extract_user
[2022-09-14 05:03:09,245] {task_command.py:369} INFO - Running <TaskInstance: user_processing.extract_user __airflow_temporary_run_2022-09-14T05:03:07.882955+00:00__ [running]> on host 5282528dd996
[2022-09-14 05:03:09,298] {taskinstance.py:1571} INFO - Exporting the following env vars:
AIRFLOW_CTX_DAG_OWNER=***
AIRFLOW_CTX_DAG_ID=user_processing
AIRFLOW_CTX_TASK_ID=extract_user
AIRFLOW_CTX_EXECUTION_DATE=2022-01-01T00:00:00+00:00
AIRFLOW_CTX_TRY_NUMBER=1
AIRFLOW_CTX_DAG_RUN_ID=__***_temporary_run_2022-09-14T05:03:07.882955+00:00__
[2022-09-14 05:03:09,301] {http.py:102} INFO - Calling HTTP method
[2022-09-14 05:03:09,308] {base.py:68} INFO - Using connection ID 'user_api' for task execution.
[2022-09-14 05:03:09,310] {http.py:129} INFO - Sending 'GET' to url: https://randomuser.me/api/
[2022-09-14 05:03:14,301] {local_task_job.py:221} WARNING - State of this instance has been externally set to None. Terminating instance.
[2022-09-14 05:03:14,309] {process_utils.py:129} INFO - Sending Signals.SIGTERM to group 13709. PIDs of all processes in the group: [13709]
[2022-09-14 05:03:14,310] {process_utils.py:80} INFO - Sending the signal Signals.SIGTERM to group 13709
[2022-09-14 05:03:14,312] {taskinstance.py:1541} ERROR - Received SIGTERM. Terminating subprocesses.
[2022-09-14 05:03:14,336] {taskinstance.py:1889} ERROR - Task failed with exception
Traceback (most recent call last):
  File "/home/airflow/.local/lib/python3.7/site-packages/airflow/providers/http/operators/http.py", line 104, in execute
    response = http.run(self.endpoint, self.data, self.headers, self.extra_options)
  File "/home/airflow/.local/lib/python3.7/site-packages/airflow/providers/http/hooks/http.py", line 130, in run
    return self.run_and_check(session, prepped_request, extra_options)
  File "/home/airflow/.local/lib/python3.7/site-packages/airflow/providers/http/hooks/http.py", line 180, in run_and_check
    response = session.send(prepped_request, **send_kwargs)
  File "/home/airflow/.local/lib/python3.7/site-packages/requests/sessions.py", line 645, in send
    r = adapter.send(request, **kwargs)
  File "/home/airflow/.local/lib/python3.7/site-packages/requests/adapters.py", line 450, in send
    timeout=timeout
  File "/home/airflow/.local/lib/python3.7/site-packages/urllib3/connectionpool.py", line 710, in urlopen
    chunked=chunked,
  File "/home/airflow/.local/lib/python3.7/site-packages/urllib3/connectionpool.py", line 449, in _make_request
    six.raise_from(e, None)
  File "<string>", line 3, in raise_from
  File "/home/airflow/.local/lib/python3.7/site-packages/urllib3/connectionpool.py", line 444, in _make_request
    httplib_response = conn.getresponse()
  File "/usr/local/lib/python3.7/http/client.py", line 1373, in getresponse
    response.begin()
  File "/usr/local/lib/python3.7/http/client.py", line 319, in begin
    version, status, reason = self._read_status()
  File "/usr/local/lib/python3.7/http/client.py", line 280, in _read_status
    line = str(self.fp.readline(_MAXLINE + 1), "iso-8859-1")
  File "/usr/local/lib/python3.7/socket.py", line 589, in readinto
    return self._sock.recv_into(b)
  File "/usr/local/lib/python3.7/ssl.py", line 1071, in recv_into
    return self.read(nbytes, buffer)
  File "/usr/local/lib/python3.7/ssl.py", line 929, in read
    return self._sslobj.read(len, buffer)
  File "/home/airflow/.local/lib/python3.7/site-packages/airflow/models/taskinstance.py", line 1543, in signal_handler
    raise AirflowException("Task received SIGTERM signal")
airflow.exceptions.AirflowException: Task received SIGTERM signal
[2022-09-14 05:03:14,346] {taskinstance.py:1400} INFO - Marking task as FAILED. dag_id=user_processing, task_id=extract_user, execution_date=20220101T000000, start_date=20220914T050309, end_date=20220914T050314
[2022-09-14 05:03:14,358] {standard_task_runner.py:97} ERROR - Failed to execute job 33 for task extract_user ((psycopg2.errors.ForeignKeyViolation) insert or update on table "task_fail" violates foreign key constraint "task_fail_ti_fkey"
DETAIL:  Key (dag_id, task_id, run_id, map_index)=(user_processing, extract_user, __airflow_temporary_run_2022-09-14T05:03:07.882955+00:00__, -1) is not present in table "task_instance".

[SQL: INSERT INTO task_fail (task_id, dag_id, run_id, map_index, start_date, end_date, duration) VALUES (%(task_id)s, %(dag_id)s, %(run_id)s, %(map_index)s, %(start_date)s, %(end_date)s, %(duration)s) RETURNING task_fail.id]
[parameters: {'task_id': 'extract_user', 'dag_id': 'user_processing', 'run_id': '__airflow_temporary_run_2022-09-14T05:03:07.882955+00:00__', 'map_index': -1, 'start_date': datetime.datetime(2022, 9, 14, 5, 3, 9, 175428, tzinfo=Timezone('UTC')), 'end_date': datetime.datetime(2022, 9, 14, 5, 3, 14, 345285, tzinfo=Timezone('UTC')), 'duration': 5}]
(Background on this error at: http://sqlalche.me/e/14/gkpj); 13709)
[2022-09-14 05:03:14,404] {process_utils.py:75} INFO - Process psutil.Process(pid=13709, status='terminated', exitcode=1, started='05:03:08') (13709) terminated with exit code 1
