[2022-09-14 05:05:22,945] {taskinstance.py:1159} INFO - Dependencies all met for <TaskInstance: user_processing.process_user __airflow_temporary_run_2022-09-14T05:05:21.410315+00:00__ [queued]>
[2022-09-14 05:05:22,974] {taskinstance.py:1159} INFO - Dependencies all met for <TaskInstance: user_processing.process_user __airflow_temporary_run_2022-09-14T05:05:21.410315+00:00__ [queued]>
[2022-09-14 05:05:22,975] {taskinstance.py:1356} INFO - 
--------------------------------------------------------------------------------
[2022-09-14 05:05:22,976] {taskinstance.py:1357} INFO - Starting attempt 1 of 1
[2022-09-14 05:05:22,977] {taskinstance.py:1358} INFO - 
--------------------------------------------------------------------------------
[2022-09-14 05:05:23,034] {taskinstance.py:1377} INFO - Executing <Task(PythonOperator): process_user> on 2022-09-14 00:00:00+00:00
[2022-09-14 05:05:23,062] {standard_task_runner.py:52} INFO - Started process 13831 to run task
[2022-09-14 05:05:23,072] {standard_task_runner.py:79} INFO - Running: ['***', 'tasks', 'run', 'user_processing', 'process_user', '__***_temporary_run_2022-09-14T05:05:21.410315+00:00__', '--job-id', '36', '--raw', '--subdir', 'DAGS_FOLDER/user_processing.py', '--cfg-path', '/tmp/tmpn8zvux3f', '--error-file', '/tmp/tmpibjs62sq']
[2022-09-14 05:05:23,075] {standard_task_runner.py:80} INFO - Job 36: Subtask process_user
[2022-09-14 05:05:23,300] {task_command.py:369} INFO - Running <TaskInstance: user_processing.process_user __airflow_temporary_run_2022-09-14T05:05:21.410315+00:00__ [running]> on host 5282528dd996
[2022-09-14 05:05:23,580] {taskinstance.py:1571} INFO - Exporting the following env vars:
AIRFLOW_CTX_DAG_OWNER=***
AIRFLOW_CTX_DAG_ID=user_processing
AIRFLOW_CTX_TASK_ID=process_user
AIRFLOW_CTX_EXECUTION_DATE=2022-09-14T00:00:00+00:00
AIRFLOW_CTX_TRY_NUMBER=1
AIRFLOW_CTX_DAG_RUN_ID=__***_temporary_run_2022-09-14T05:05:21.410315+00:00__
[2022-09-14 05:05:23,621] {taskinstance.py:1889} ERROR - Task failed with exception
Traceback (most recent call last):
  File "/home/airflow/.local/lib/python3.7/site-packages/airflow/operators/python.py", line 171, in execute
    return_value = self.execute_callable()
  File "/home/airflow/.local/lib/python3.7/site-packages/airflow/operators/python.py", line 189, in execute_callable
    return self.python_callable(*self.op_args, **self.op_kwargs)
  File "/opt/airflow/dags/user_processing.py", line 14, in _process_user
    user= user['results'][0]
TypeError: 'NoneType' object is not subscriptable
[2022-09-14 05:05:23,645] {taskinstance.py:1400} INFO - Marking task as FAILED. dag_id=user_processing, task_id=process_user, execution_date=20220914T000000, start_date=20220914T050522, end_date=20220914T050523
[2022-09-14 05:05:23,677] {standard_task_runner.py:97} ERROR - Failed to execute job 36 for task process_user ('NoneType' object is not subscriptable; 13831)
[2022-09-14 05:05:23,704] {local_task_job.py:156} INFO - Task exited with return code 1
[2022-09-14 05:05:23,773] {local_task_job.py:273} INFO - 0 downstream tasks scheduled from follow-on schedule check
